<mujoco model="feixi_model"> 
  <compiler angle="radian" autolimits="true"/>
  <option timestep="0.002" integrator="implicitfast" gravity="0 0 -9.81"/>

  <default>
    <joint type="hinge" damping="0.5" armature="0.01"/>
    <!--转动关节，阻尼，附加转动惯量。-->
    <motor ctrllimited="true"/>

    <!-- Visual meshes: render only, no contact. -->
    <default class="visual">
      <geom type="mesh" contype="0" conaffinity="0" group="1" rgba="0.75 0.75 0.75 1"/>
    </default>

    <!-- Collision meshes: contact only, hidden by default. -->
    <default class="collision">
      <geom type="mesh" contype="1" conaffinity="1" group="3" rgba="0 0 0 0"/>
    </default>
  </default>

  <asset>
    <mesh name="link0_v" file="visual/link0.obj"/>
    <mesh name="link1_v" file="visual/link1.obj"/>
    <mesh name="link2_v" file="visual/link2.obj"/>
    <mesh name="link3_v" file="visual/link3.obj"/>
    <mesh name="link4_v" file="visual/link4.obj"/>
    <mesh name="link5_v" file="visual/link5.obj"/>
    <mesh name="link6_v" file="visual/link6.obj"/>
    <mesh name="link7_v" file="visual/link7.obj"/>

    <!-- Placeholder collision meshes. Swap to collision/*.stl when available. -->
    <mesh name="link0_c" file="collision/link0.obj"/>
    <mesh name="link1_c" file="collision/link1.obj"/>
    <mesh name="link2_c" file="collision/link2.obj"/>
    <mesh name="link3_c" file="collision/link3.obj"/>
    <mesh name="link4_c" file="collision/link4.obj"/>
    <mesh name="link5_c" file="collision/link5.obj"/>
    <mesh name="link6_c" file="collision/link6.obj"/>
    <mesh name="link7_c" file="collision/link7.obj"/>
  </asset>

  <worldbody>
    <geom name="ground" type="plane" size="5 5 0.1" rgba="0.2 0.3 0.4 1"/>
    <body name="base_link">
      <geom class="visual" mesh="link0_v"/>
      <geom class="collision" mesh="link0_c"/>

      <body name="link1" pos="0 0 0.21" euler="0 0 -3.141592653589793">
        <joint name="joint1" axis="0 0 1" range="-2.8798 2.8798"/>
        <geom class="visual" mesh="link1_v"/>
        <geom class="collision" mesh="link1_c"/>

        <body name="link2" pos="0 0.0675 0.24">
          <joint name="joint2" axis="0 1 0" range="-2.7576 2.7576"/>
          <geom class="visual" mesh="link2_v"/>
          <geom class="collision" mesh="link2_c"/>

          <body name="link3" pos="0 0.0625 0.2275">
            <joint name="joint3" axis="0 0 1" range="-2.8798 2.8798"/>
            <geom class="visual" mesh="link3_v"/>
            <geom class="collision" mesh="link3_c"/>

            <body name="link4" pos="0 -0.0625 0.2225" euler="0 0 -3.141592653589793">
              <joint name="joint4" axis="0 1 0" range="-2.7925 2.7925"/>
              <geom class="visual" mesh="link4_v"/>
              <geom class="collision" mesh="link4_c"/>

              <body name="link5" pos="0 0.0575 0.205" euler="0 0 -3.141592653589793">
                <joint name="joint5" axis="0 0 1" range="-3.0543 3.0543"/>
                <geom class="visual" mesh="link5_v"/>
                <geom class="collision" mesh="link5_c"/>

                <body name="link6" pos="0 0.03 0.19">
                  <joint name="joint6" axis="0 1 0" range="-1.4835 4.6251"/>
                  <geom class="visual" mesh="link6_v"/>
                  <geom class="collision" mesh="link6_c"/>

                  <body name="link7" pos="-0.015 0.073 0.11" euler="0 -1.5707963478683205 0">
                    <joint name="joint7" axis="0 0 1" range="-3.0543 3.0543"/>
                    <geom class="visual" mesh="link7_v"/>
                    <geom class="collision" mesh="link7_c"/>
                  </body>
                </body>
              </body>
            </body>
          </body>
        </body>
      </body>
    </body>
  </worldbody>

  <actuator>
    <motor name="m_joint1" joint="joint1" ctrlrange="-261 261" gear="1"/>
    <motor name="m_joint2" joint="joint2" ctrlrange="-261 261" gear="1"/>
    <motor name="m_joint3" joint="joint3" ctrlrange="-123 123" gear="1"/>
    <motor name="m_joint4" joint="joint4" ctrlrange="-123 123" gear="1"/>
    <motor name="m_joint5" joint="joint5" ctrlrange="-57 57" gear="1"/>
    <motor name="m_joint6" joint="joint6" ctrlrange="-57 57" gear="1"/>
    <motor name="m_joint7" joint="joint7" ctrlrange="-57 57" gear="1"/>
  </actuator>
</mujoco>
